<?xml version="1.0" ?><root>
<report><version>2</version><sessionid>13b6ff1315dcf3f5ed46fcc</sessionid><type>desync</type><sku>ea.maxis.sims4.13.pc</sku><createtime>2020-06-01 09:48:37</createtime><buildsignature>Local.Unknown.Unknown.1.53.115.1020-1.200.000.400.Release</buildsignature><categoryid>test_variants.py:2879</categoryid><desyncid>13b6ff1315dcf3f5ed46fcc</desyncid><systemconfig/><screenshot/><desyncdata>Exception raised while trying to run a test event in test_events.py: (AttributeError: type object 'aspiration_Utility_Max_GourmetCooking' has no attribute 'complete_only_in_sequence')&#13;&#10;Traceback (most recent call last):&#13;&#10;Caught and logged:&#13;&#10;  File "T:\InGame\Gameplay\Scripts\Core\sims4\utils.py", line 179, in wrapper&#13;&#10;  File "T:\InGame\Gameplay\Scripts\Server\areaserver.py", line 206, in c_api_server_tick&#13;&#10;  File "T:\InGame\Gameplay\Scripts\Server\zone.py", line 463, in update&#13;&#10;  File "T:\InGame\Gameplay\Scripts\Server\time_service.py", line 112, in update&#13;&#10;  File "T:\InGame\Gameplay\Scripts\Server\scheduling.py", line 212, in simulate&#13;&#10;  File "T:\InGame\Gameplay\Scripts\Server\elements.py", line 376, in _run&#13;&#10;  File "T:\InGame\Gameplay\Scripts\Server\carry\carry_elements.py", line 442, in maybe_do_transition&#13;&#10;  File "T:\InGame\Gameplay\Scripts\Server\crafting\crafting_interactions.py", line 1879, in callback&#13;&#10;  File "T:\InGame\Gameplay\Scripts\Server\crafting\crafting_interactions.py", line 2211, in _custom_claim_callback&#13;&#10;  File "T:\InGame\Gameplay\Scripts\Server\crafting\crafting_interactions.py", line 1802, in _custom_claim_callback&#13;&#10;  File "T:\InGame\Gameplay\Scripts\Server\interactions\utils\loot.py", line 101, in apply_operations&#13;&#10;  File "T:\InGame\Gameplay\Scripts\Server\interactions\utils\loot.py", line 406, in apply_to_resolver&#13;&#10;  File "T:\InGame\Gameplay\Scripts\Server\interactions\utils\loot_basic_op.py", line 209, in apply_to_resolver&#13;&#10;  File "T:\InGame\Gameplay\Scripts\Server\statistics\statistic_ops.py", line 146, in _apply_to_subject_and_target&#13;&#10;  File "T:\InGame\Gameplay\Scripts\Server\statistics\statistic_ops.py", line 441, in _apply&#13;&#10;  File "T:\InGame\Gameplay\Scripts\Server\statistics\commodity_tracker.py", line 72, in add_value&#13;&#10;  File "T:\InGame\Gameplay\Scripts\Server\statistics\base_statistic_tracker.py", line 395, in add_value&#13;&#10;  File "T:\InGame\Gameplay\Scripts\Server\statistics\skill.py", line 848, in add_value&#13;&#10;  File "T:\InGame\Gameplay\Scripts\Server\statistics\base_statistic.py", line 308, in add_value&#13;&#10;  File "T:\InGame\Gameplay\Scripts\Server\statistics\base_statistic.py", line 332, in _add_value&#13;&#10;  File "T:\InGame\Gameplay\Scripts\Server\statistics\skill.py", line 835, in set_value&#13;&#10;  File "T:\InGame\Gameplay\Scripts\Server\event_testing\event_manager_service.py", line 256, in process_event&#13;&#10;  File "T:\InGame\Gameplay\Scripts\Server\event_testing\event_manager_service.py", line 363, in _process_test_event&#13;&#10;  File "T:\InGame\Gameplay\Scripts\Server\aspirations\aspiration_tuning.py", line 64, in handle_event&#13;&#10;  File "T:\InGame\Gameplay\Scripts\Server\event_testing\event_data_tracker.py", line 206, in handle_event&#13;&#10;  File "T:\InGame\Gameplay\Scripts\Server\aspirations\aspirations.py", line 345, in complete_milestone&#13;&#10;  File "T:\InGame\Gameplay\Scripts\Server\event_testing\event_manager_service.py", line 256, in process_event&#13;&#10;  File "T:\InGame\Gameplay\Scripts\Server\event_testing\event_manager_service.py", line 365, in _process_test_event&#13;&#10;  File "T:\InGame\Gameplay\Scripts\Server\event_testing\test_events.py", line 168, in wrapper&#13;&#10;KeyError: (&lt;event_testing.test_variants.UnlockedTest object at 0x57F05F48&gt;, frozenset({('sims', (&lt;sim '' 0xc5e0a8c54960a7e&gt;,)), ('unlocked', &lt;class 'sims4.tuning.instances.aspiration_Utility_Max_GourmetCooking'&gt;)}))&#13;&#10;&#13;&#10;During handling of the above exception, another exception occurred:&#13;&#10;&#13;&#10;Traceback (most recent call last):&#13;&#10;  File "T:\InGame\Gameplay\Scripts\Server\event_testing\event_manager_service.py", line 363, in _process_test_event&#13;&#10;  File "T:\InGame\Gameplay\Scripts\Server\aspirations\aspiration_tuning.py", line 64, in handle_event&#13;&#10;  File "T:\InGame\Gameplay\Scripts\Server\event_testing\event_data_tracker.py", line 185, in handle_event&#13;&#10;  File "T:\InGame\Gameplay\Scripts\Server\event_testing\objective_tuning.py", line 1037, in run_test&#13;&#10;  File "T:\InGame\Gameplay\Scripts\Server\event_testing\resolver.py", line 790, in __call__&#13;&#10;  File "T:\InGame\Gameplay\Scripts\Server\event_testing\resolver.py", line 129, in __call__&#13;&#10;  File "T:\InGame\Gameplay\Scripts\Server\event_testing\test_events.py", line 170, in wrapper&#13;&#10;  File "T:\InGame\Gameplay\Scripts\Server\event_testing\test_variants.py", line 2969, in __call__&#13;&#10;  File "T:\InGame\Gameplay\Scripts\Server\event_testing\test_variants.py", line 2879, in __call__&#13;&#10;AttributeError: type object 'aspiration_Utility_Max_GourmetCooking' has no attribute 'complete_only_in_sequence'&#13;&#10;rtim=0</desyncdata></report>
</root>